2025-04-03 19:23:51.160000: I tensorflow/core/util/port.cc:153] oneDNN custom operations are on. You may see slightly different numerical results due to floating-point round-off errors from different computation orders. To turn them off, set the environment variable `TF_ENABLE_ONEDNN_OPTS=0`.
2025-04-03 19:23:51.160408: I external/local_xla/xla/tsl/cuda/cudart_stub.cc:32] Could not find cuda drivers on your machine, GPU will not be used.
2025-04-03 19:23:51.162329: I external/local_xla/xla/tsl/cuda/cudart_stub.cc:32] Could not find cuda drivers on your machine, GPU will not be used.
2025-04-03 19:23:51.167566: E external/local_xla/xla/stream_executor/cuda/cuda_fft.cc:467] Unable to register cuFFT factory: Attempting to register factory for plugin cuFFT when one has already been registered
WARNING: All log messages before absl::InitializeLog() is called are written to STDERR
E0000 00:00:1743704631.176347   70117 cuda_dnn.cc:8579] Unable to register cuDNN factory: Attempting to register factory for plugin cuDNN when one has already been registered
E0000 00:00:1743704631.178893   70117 cuda_blas.cc:1407] Unable to register cuBLAS factory: Attempting to register factory for plugin cuBLAS when one has already been registered
W0000 00:00:1743704631.185722   70117 computation_placer.cc:177] computation placer already registered. Please check linkage and avoid linking the same target more than once.
W0000 00:00:1743704631.185766   70117 computation_placer.cc:177] computation placer already registered. Please check linkage and avoid linking the same target more than once.
W0000 00:00:1743704631.185770   70117 computation_placer.cc:177] computation placer already registered. Please check linkage and avoid linking the same target more than once.
W0000 00:00:1743704631.185771   70117 computation_placer.cc:177] computation placer already registered. Please check linkage and avoid linking the same target more than once.
2025-04-03 19:23:51.187983: I tensorflow/core/platform/cpu_feature_guard.cc:210] This TensorFlow binary is optimized to use available CPU instructions in performance-critical operations.
To enable the following instructions: AVX2 AVX_VNNI FMA, in other operations, rebuild TensorFlow with the appropriate compiler flags.
[93mWARNING [0m:   DEPRECATED FEATURE: flwr.simulation.start_simulation() is deprecated.
	Instead, use the `flwr run` CLI command to start a local simulation in your Flower app, as shown for example below:

		$ flwr new  # Create a new Flower app from a template

		$ flwr run  # Run the Flower app in Simulation Mode

	Using `start_simulation()` is deprecated.

            This is a deprecated feature. It will be removed
            entirely in future versions of Flower.
        
[92mINFO [0m:      Starting Flower simulation, config: num_rounds=5, no round_timeout
2025-04-03 19:23:55,565	INFO worker.py:1771 -- Started a local Ray instance.
[92mINFO [0m:      Flower VCE: Ray initialized with resources: {'accelerator_type:G': 1.0, 'node:__internal_head__': 1.0, 'CPU': 8.0, 'object_store_memory': 3076866048.0, 'memory': 6153732096.0, 'GPU': 1.0, 'node:192.168.52.78': 1.0}
[92mINFO [0m:      Optimize your simulation with Flower VCE: https://flower.ai/docs/framework/how-to-run-simulations.html
[92mINFO [0m:      Flower VCE: Resources for each Virtual Client: {'num_cpus': 1}
[92mINFO [0m:      Flower VCE: Creating VirtualClientEngineActorPool with 8 actors
[92mINFO [0m:      [INIT]
[92mINFO [0m:      Requesting initial parameters from one random client
[36m(pid=70865)[0m 2025-04-03 19:23:56.627624: I tensorflow/core/util/port.cc:153] oneDNN custom operations are on. You may see slightly different numerical results due to floating-point round-off errors from different computation orders. To turn them off, set the environment variable `TF_ENABLE_ONEDNN_OPTS=0`.
[36m(pid=70865)[0m 2025-04-03 19:23:56.628366: I external/local_xla/xla/tsl/cuda/cudart_stub.cc:32] Could not find cuda drivers on your machine, GPU will not be used.
[36m(pid=70866)[0m 2025-04-03 19:23:56.674855: E external/local_xla/xla/stream_executor/cuda/cuda_fft.cc:467] Unable to register cuFFT factory: Attempting to register factory for plugin cuFFT when one has already been registered
[36m(pid=70866)[0m WARNING: All log messages before absl::InitializeLog() is called are written to STDERR
[36m(pid=70866)[0m E0000 00:00:1743704636.690500   70866 cuda_dnn.cc:8579] Unable to register cuDNN factory: Attempting to register factory for plugin cuDNN when one has already been registered
[36m(pid=70866)[0m E0000 00:00:1743704636.693890   70866 cuda_blas.cc:1407] Unable to register cuBLAS factory: Attempting to register factory for plugin cuBLAS when one has already been registered
[36m(pid=70866)[0m W0000 00:00:1743704636.702966   70866 computation_placer.cc:177] computation placer already registered. Please check linkage and avoid linking the same target more than once.
[36m(pid=70866)[0m W0000 00:00:1743704636.702985   70866 computation_placer.cc:177] computation placer already registered. Please check linkage and avoid linking the same target more than once.
[36m(pid=70866)[0m W0000 00:00:1743704636.702986   70866 computation_placer.cc:177] computation placer already registered. Please check linkage and avoid linking the same target more than once.
[36m(pid=70866)[0m W0000 00:00:1743704636.702987   70866 computation_placer.cc:177] computation placer already registered. Please check linkage and avoid linking the same target more than once.
[36m(pid=70866)[0m 2025-04-03 19:23:56.705889: I tensorflow/core/platform/cpu_feature_guard.cc:210] This TensorFlow binary is optimized to use available CPU instructions in performance-critical operations.
[36m(pid=70866)[0m To enable the following instructions: AVX2 AVX_VNNI FMA, in other operations, rebuild TensorFlow with the appropriate compiler flags.
[36m(ClientAppActor pid=70868)[0m [93mWARNING [0m:   DEPRECATED FEATURE: `client_fn` now expects a signature `def client_fn(context: Context)`.The provided `client_fn` has signature: {'cid': <Parameter "cid: str">}. You can import the `Context` like this: `from flwr.common import Context`
[36m(ClientAppActor pid=70868)[0m 
[36m(ClientAppActor pid=70868)[0m             This is a deprecated feature. It will be removed
[36m(ClientAppActor pid=70868)[0m             entirely in future versions of Flower.
[36m(ClientAppActor pid=70868)[0m         
[36m(ClientAppActor pid=70868)[0m 2025-04-03 19:23:59.253411: E external/local_xla/xla/stream_executor/cuda/cuda_platform.cc:51] failed call to cuInit: INTERNAL: CUDA error: Failed call to cuInit: CUDA_ERROR_NO_DEVICE: no CUDA-capable device is detected
[91mERROR [0m:     Traceback (most recent call last):
  File "/home/timotei/venv/lib/python3.12/site-packages/flwr/simulation/ray_transport/ray_client_proxy.py", line 95, in _submit_job
    out_mssg, updated_context = self.actor_pool.get_client_result(
                                ^^^^^^^^^^^^^^^^^^^^^^^^^^^^^^^^^^
  File "/home/timotei/venv/lib/python3.12/site-packages/flwr/simulation/ray_transport/ray_actor.py", line 401, in get_client_result
    return self._fetch_future_result(cid)
           ^^^^^^^^^^^^^^^^^^^^^^^^^^^^^^
  File "/home/timotei/venv/lib/python3.12/site-packages/flwr/simulation/ray_transport/ray_actor.py", line 282, in _fetch_future_result
    res_cid, out_mssg, updated_context = ray.get(
                                         ^^^^^^^^
  File "/home/timotei/venv/lib/python3.12/site-packages/ray/_private/auto_init_hook.py", line 21, in auto_init_wrapper
    return fn(*args, **kwargs)
           ^^^^^^^^^^^^^^^^^^^
  File "/home/timotei/venv/lib/python3.12/site-packages/ray/_private/client_mode_hook.py", line 103, in wrapper
    return func(*args, **kwargs)
           ^^^^^^^^^^^^^^^^^^^^^
  File "/home/timotei/venv/lib/python3.12/site-packages/ray/_private/worker.py", line 2639, in get
    values, debugger_breakpoint = worker.get_objects(object_refs, timeout=timeout)
                                  ^^^^^^^^^^^^^^^^^^^^^^^^^^^^^^^^^^^^^^^^^^^^^^^^
  File "/home/timotei/venv/lib/python3.12/site-packages/ray/_private/worker.py", line 864, in get_objects
    raise value.as_instanceof_cause()
ray.exceptions.RayTaskError(ClientAppException): [36mray::ClientAppActor.run()[39m (pid=70868, ip=192.168.52.78, actor_id=b600b7835a21c5010eed2b8201000000, repr=<flwr.simulation.ray_transport.ray_actor.ClientAppActor object at 0x7f6fa6946030>)
                  ^^^^^^^^^^^^^^^^^^^^^^^^^^^^^^^^^^^^^
  File "/home/timotei/venv/lib/python3.12/site-packages/flwr/client/client_app.py", line 144, in __call__
    return self._call(message, context)
           ^^^^^^^^^^^^^^^^^^^^^^^^^^^^
  File "/home/timotei/venv/lib/python3.12/site-packages/flwr/client/client_app.py", line 128, in ffn
    out_message = handle_legacy_message_from_msgtype(
                  ^^^^^^^^^^^^^^^^^^^^^^^^^^^^^^^^^^^
  File "/home/timotei/venv/lib/python3.12/site-packages/flwr/client/message_handler/message_handler.py", line 123, in handle_legacy_message_from_msgtype
    out_recorddict = getparametersres_to_recorddict(
                     ^^^^^^^^^^^^^^^^^^^^^^^^^^^^^^^
  File "/home/timotei/venv/lib/python3.12/site-packages/flwr/common/recorddict_compat.py", line 343, in getparametersres_to_recorddict
    getparametersres.parameters, keep_input=keep_input
    ^^^^^^^^^^^^^^^^^^^^^^^^^^^
AttributeError: 'Parameters' object has no attribute 'parameters'

The above exception was the direct cause of the following exception:

[36mray::ClientAppActor.run()[39m (pid=70868, ip=192.168.52.78, actor_id=b600b7835a21c5010eed2b8201000000, repr=<flwr.simulation.ray_transport.ray_actor.ClientAppActor object at 0x7f6fa6946030>)
           ^^^^^^^^^^^^^^^^^^^^^^^^^^^^^^^^^^^^
           ^^^^^^^^^^^^^^^^^^^^^^^^^^^^^^^
  File "/home/timotei/venv/lib/python3.12/site-packages/flwr/simulation/ray_transport/ray_actor.py", line 64, in run
    raise ClientAppException(str(ex)) from ex
flwr.client.client_app.ClientAppException: 
Exception ClientAppException occurred. Message: 'Parameters' object has no attribute 'parameters'

[91mERROR [0m:     [36mray::ClientAppActor.run()[39m (pid=70868, ip=192.168.52.78, actor_id=b600b7835a21c5010eed2b8201000000, repr=<flwr.simulation.ray_transport.ray_actor.ClientAppActor object at 0x7f6fa6946030>)
                  ^^^^^^^^^^^^^^^^^^^^^^^^^^^^^^^^^^^^^
  File "/home/timotei/venv/lib/python3.12/site-packages/flwr/client/client_app.py", line 144, in __call__
    return self._call(message, context)
           ^^^^^^^^^^^^^^^^^^^^^^^^^^^^
  File "/home/timotei/venv/lib/python3.12/site-packages/flwr/client/client_app.py", line 128, in ffn
    out_message = handle_legacy_message_from_msgtype(
                  ^^^^^^^^^^^^^^^^^^^^^^^^^^^^^^^^^^^
  File "/home/timotei/venv/lib/python3.12/site-packages/flwr/client/message_handler/message_handler.py", line 123, in handle_legacy_message_from_msgtype
    out_recorddict = getparametersres_to_recorddict(
                     ^^^^^^^^^^^^^^^^^^^^^^^^^^^^^^^
  File "/home/timotei/venv/lib/python3.12/site-packages/flwr/common/recorddict_compat.py", line 343, in getparametersres_to_recorddict
    getparametersres.parameters, keep_input=keep_input
    ^^^^^^^^^^^^^^^^^^^^^^^^^^^
AttributeError: 'Parameters' object has no attribute 'parameters'

The above exception was the direct cause of the following exception:

[36mray::ClientAppActor.run()[39m (pid=70868, ip=192.168.52.78, actor_id=b600b7835a21c5010eed2b8201000000, repr=<flwr.simulation.ray_transport.ray_actor.ClientAppActor object at 0x7f6fa6946030>)
           ^^^^^^^^^^^^^^^^^^^^^^^^^^^^^^^^^^^^
           ^^^^^^^^^^^^^^^^^^^^^^^^^^^^^^^
  File "/home/timotei/venv/lib/python3.12/site-packages/flwr/simulation/ray_transport/ray_actor.py", line 64, in run
    raise ClientAppException(str(ex)) from ex
flwr.client.client_app.ClientAppException: 
Exception ClientAppException occurred. Message: 'Parameters' object has no attribute 'parameters'
[91mERROR [0m:     [36mray::ClientAppActor.run()[39m (pid=70868, ip=192.168.52.78, actor_id=b600b7835a21c5010eed2b8201000000, repr=<flwr.simulation.ray_transport.ray_actor.ClientAppActor object at 0x7f6fa6946030>)
                  ^^^^^^^^^^^^^^^^^^^^^^^^^^^^^^^^^^^^^
  File "/home/timotei/venv/lib/python3.12/site-packages/flwr/client/client_app.py", line 144, in __call__
    return self._call(message, context)
           ^^^^^^^^^^^^^^^^^^^^^^^^^^^^
  File "/home/timotei/venv/lib/python3.12/site-packages/flwr/client/client_app.py", line 128, in ffn
    out_message = handle_legacy_message_from_msgtype(
                  ^^^^^^^^^^^^^^^^^^^^^^^^^^^^^^^^^^^
  File "/home/timotei/venv/lib/python3.12/site-packages/flwr/client/message_handler/message_handler.py", line 123, in handle_legacy_message_from_msgtype
    out_recorddict = getparametersres_to_recorddict(
                     ^^^^^^^^^^^^^^^^^^^^^^^^^^^^^^^
  File "/home/timotei/venv/lib/python3.12/site-packages/flwr/common/recorddict_compat.py", line 343, in getparametersres_to_recorddict
    getparametersres.parameters, keep_input=keep_input
    ^^^^^^^^^^^^^^^^^^^^^^^^^^^
AttributeError: 'Parameters' object has no attribute 'parameters'

The above exception was the direct cause of the following exception:

[36mray::ClientAppActor.run()[39m (pid=70868, ip=192.168.52.78, actor_id=b600b7835a21c5010eed2b8201000000, repr=<flwr.simulation.ray_transport.ray_actor.ClientAppActor object at 0x7f6fa6946030>)
           ^^^^^^^^^^^^^^^^^^^^^^^^^^^^^^^^^^^^
           ^^^^^^^^^^^^^^^^^^^^^^^^^^^^^^^
  File "/home/timotei/venv/lib/python3.12/site-packages/flwr/simulation/ray_transport/ray_actor.py", line 64, in run
    raise ClientAppException(str(ex)) from ex
flwr.client.client_app.ClientAppException: 
Exception ClientAppException occurred. Message: 'Parameters' object has no attribute 'parameters'
[91mERROR [0m:     Traceback (most recent call last):
  File "/home/timotei/venv/lib/python3.12/site-packages/flwr/simulation/legacy_app.py", line 361, in start_simulation
    hist = run_fl(
           ^^^^^^^
  File "/home/timotei/venv/lib/python3.12/site-packages/flwr/server/server.py", line 492, in run_fl
    hist, elapsed_time = server.fit(
                         ^^^^^^^^^^^
  File "/home/timotei/venv/lib/python3.12/site-packages/flwr/server/server.py", line 93, in fit
    self.parameters = self._get_initial_parameters(server_round=0, timeout=timeout)
                      ^^^^^^^^^^^^^^^^^^^^^^^^^^^^^^^^^^^^^^^^^^^^^^^^^^^^^^^^^^^^^
  File "/home/timotei/venv/lib/python3.12/site-packages/flwr/server/server.py", line 284, in _get_initial_parameters
    get_parameters_res = random_client.get_parameters(
                         ^^^^^^^^^^^^^^^^^^^^^^^^^^^^^
  File "/home/timotei/venv/lib/python3.12/site-packages/flwr/simulation/ray_transport/ray_client_proxy.py", line 170, in get_parameters
    message_out = self._submit_job(message, timeout)
                  ^^^^^^^^^^^^^^^^^^^^^^^^^^^^^^^^^^
  File "/home/timotei/venv/lib/python3.12/site-packages/flwr/simulation/ray_transport/ray_client_proxy.py", line 109, in _submit_job
    raise ex
  File "/home/timotei/venv/lib/python3.12/site-packages/flwr/simulation/ray_transport/ray_client_proxy.py", line 95, in _submit_job
    out_mssg, updated_context = self.actor_pool.get_client_result(
                                ^^^^^^^^^^^^^^^^^^^^^^^^^^^^^^^^^^
  File "/home/timotei/venv/lib/python3.12/site-packages/flwr/simulation/ray_transport/ray_actor.py", line 401, in get_client_result
    return self._fetch_future_result(cid)
           ^^^^^^^^^^^^^^^^^^^^^^^^^^^^^^
  File "/home/timotei/venv/lib/python3.12/site-packages/flwr/simulation/ray_transport/ray_actor.py", line 282, in _fetch_future_result
    res_cid, out_mssg, updated_context = ray.get(
                                         ^^^^^^^^
  File "/home/timotei/venv/lib/python3.12/site-packages/ray/_private/auto_init_hook.py", line 21, in auto_init_wrapper
    return fn(*args, **kwargs)
           ^^^^^^^^^^^^^^^^^^^
  File "/home/timotei/venv/lib/python3.12/site-packages/ray/_private/client_mode_hook.py", line 103, in wrapper
    return func(*args, **kwargs)
           ^^^^^^^^^^^^^^^^^^^^^
  File "/home/timotei/venv/lib/python3.12/site-packages/ray/_private/worker.py", line 2639, in get
    values, debugger_breakpoint = worker.get_objects(object_refs, timeout=timeout)
                                  ^^^^^^^^^^^^^^^^^^^^^^^^^^^^^^^^^^^^^^^^^^^^^^^^
  File "/home/timotei/venv/lib/python3.12/site-packages/ray/_private/worker.py", line 864, in get_objects
    raise value.as_instanceof_cause()
ray.exceptions.RayTaskError(ClientAppException): [36mray::ClientAppActor.run()[39m (pid=70868, ip=192.168.52.78, actor_id=b600b7835a21c5010eed2b8201000000, repr=<flwr.simulation.ray_transport.ray_actor.ClientAppActor object at 0x7f6fa6946030>)
                  ^^^^^^^^^^^^^^^^^^^^^^^^^^^^^^^^^^^^^
  File "/home/timotei/venv/lib/python3.12/site-packages/flwr/client/client_app.py", line 144, in __call__
    return self._call(message, context)
           ^^^^^^^^^^^^^^^^^^^^^^^^^^^^
  File "/home/timotei/venv/lib/python3.12/site-packages/flwr/client/client_app.py", line 128, in ffn
    out_message = handle_legacy_message_from_msgtype(
                  ^^^^^^^^^^^^^^^^^^^^^^^^^^^^^^^^^^^
  File "/home/timotei/venv/lib/python3.12/site-packages/flwr/client/message_handler/message_handler.py", line 123, in handle_legacy_message_from_msgtype
    out_recorddict = getparametersres_to_recorddict(
                     ^^^^^^^^^^^^^^^^^^^^^^^^^^^^^^^
  File "/home/timotei/venv/lib/python3.12/site-packages/flwr/common/recorddict_compat.py", line 343, in getparametersres_to_recorddict
    getparametersres.parameters, keep_input=keep_input
    ^^^^^^^^^^^^^^^^^^^^^^^^^^^
AttributeError: 'Parameters' object has no attribute 'parameters'

The above exception was the direct cause of the following exception:

[36mray::ClientAppActor.run()[39m (pid=70868, ip=192.168.52.78, actor_id=b600b7835a21c5010eed2b8201000000, repr=<flwr.simulation.ray_transport.ray_actor.ClientAppActor object at 0x7f6fa6946030>)
           ^^^^^^^^^^^^^^^^^^^^^^^^^^^^^^^^^^^^
           ^^^^^^^^^^^^^^^^^^^^^^^^^^^^^^^
  File "/home/timotei/venv/lib/python3.12/site-packages/flwr/simulation/ray_transport/ray_actor.py", line 64, in run
    raise ClientAppException(str(ex)) from ex
flwr.client.client_app.ClientAppException: 
Exception ClientAppException occurred. Message: 'Parameters' object has no attribute 'parameters'

[91mERROR [0m:     Your simulation crashed :(. This could be because of several reasons. The most common are: 
	 > Sometimes, issues in the simulation code itself can cause crashes. It's always a good idea to double-check your code for any potential bugs or inconsistencies that might be contributing to the problem. For example: 
		 - You might be using a class attribute in your clients that hasn't been defined.
		 - There could be an incorrect method call to a 3rd party library (e.g., PyTorch).
		 - The return types of methods in your clients/strategies might be incorrect.
	 > Your system couldn't fit a single VirtualClient: try lowering `client_resources`.
	 > All the actors in your pool crashed. This could be because: 
		 - You clients hit an out-of-memory (OOM) error and actors couldn't recover from it. Try launching your simulation with more generous `client_resources` setting (i.e. it seems {'num_cpus': 1} is not enough for your run). Use fewer concurrent actors. 
		 - You were running a multi-node simulation and all worker nodes disconnected. The head node might still be alive but cannot accommodate any actor with resources: {'num_cpus': 1}.
Take a look at the Flower simulation examples for guidance <https://flower.ai/docs/framework/how-to-run-simulations.html>.
Traceback (most recent call last):
  File "/home/timotei/venv/lib/python3.12/site-packages/flwr/simulation/legacy_app.py", line 361, in start_simulation
    hist = run_fl(
           ^^^^^^^
  File "/home/timotei/venv/lib/python3.12/site-packages/flwr/server/server.py", line 492, in run_fl
    hist, elapsed_time = server.fit(
                         ^^^^^^^^^^^
  File "/home/timotei/venv/lib/python3.12/site-packages/flwr/server/server.py", line 93, in fit
    self.parameters = self._get_initial_parameters(server_round=0, timeout=timeout)
                      ^^^^^^^^^^^^^^^^^^^^^^^^^^^^^^^^^^^^^^^^^^^^^^^^^^^^^^^^^^^^^
  File "/home/timotei/venv/lib/python3.12/site-packages/flwr/server/server.py", line 284, in _get_initial_parameters
    get_parameters_res = random_client.get_parameters(
                         ^^^^^^^^^^^^^^^^^^^^^^^^^^^^^
  File "/home/timotei/venv/lib/python3.12/site-packages/flwr/simulation/ray_transport/ray_client_proxy.py", line 170, in get_parameters
    message_out = self._submit_job(message, timeout)
                  ^^^^^^^^^^^^^^^^^^^^^^^^^^^^^^^^^^
  File "/home/timotei/venv/lib/python3.12/site-packages/flwr/simulation/ray_transport/ray_client_proxy.py", line 109, in _submit_job
    raise ex
  File "/home/timotei/venv/lib/python3.12/site-packages/flwr/simulation/ray_transport/ray_client_proxy.py", line 95, in _submit_job
    out_mssg, updated_context = self.actor_pool.get_client_result(
                                ^^^^^^^^^^^^^^^^^^^^^^^^^^^^^^^^^^
  File "/home/timotei/venv/lib/python3.12/site-packages/flwr/simulation/ray_transport/ray_actor.py", line 401, in get_client_result
    return self._fetch_future_result(cid)
           ^^^^^^^^^^^^^^^^^^^^^^^^^^^^^^
  File "/home/timotei/venv/lib/python3.12/site-packages/flwr/simulation/ray_transport/ray_actor.py", line 282, in _fetch_future_result
    res_cid, out_mssg, updated_context = ray.get(
                                         ^^^^^^^^
  File "/home/timotei/venv/lib/python3.12/site-packages/ray/_private/auto_init_hook.py", line 21, in auto_init_wrapper
    return fn(*args, **kwargs)
           ^^^^^^^^^^^^^^^^^^^
  File "/home/timotei/venv/lib/python3.12/site-packages/ray/_private/client_mode_hook.py", line 103, in wrapper
    return func(*args, **kwargs)
           ^^^^^^^^^^^^^^^^^^^^^
  File "/home/timotei/venv/lib/python3.12/site-packages/ray/_private/worker.py", line 2639, in get
    values, debugger_breakpoint = worker.get_objects(object_refs, timeout=timeout)
                                  ^^^^^^^^^^^^^^^^^^^^^^^^^^^^^^^^^^^^^^^^^^^^^^^^
  File "/home/timotei/venv/lib/python3.12/site-packages/ray/_private/worker.py", line 864, in get_objects
    raise value.as_instanceof_cause()
ray.exceptions.RayTaskError(ClientAppException): [36mray::ClientAppActor.run()[39m (pid=70868, ip=192.168.52.78, actor_id=b600b7835a21c5010eed2b8201000000, repr=<flwr.simulation.ray_transport.ray_actor.ClientAppActor object at 0x7f6fa6946030>)
                  ^^^^^^^^^^^^^^^^^^^^^^^^^^^^^^^^^^^^^
  File "/home/timotei/venv/lib/python3.12/site-packages/flwr/client/client_app.py", line 144, in __call__
    return self._call(message, context)
           ^^^^^^^^^^^^^^^^^^^^^^^^^^^^
  File "/home/timotei/venv/lib/python3.12/site-packages/flwr/client/client_app.py", line 128, in ffn
    out_message = handle_legacy_message_from_msgtype(
                  ^^^^^^^^^^^^^^^^^^^^^^^^^^^^^^^^^^^
  File "/home/timotei/venv/lib/python3.12/site-packages/flwr/client/message_handler/message_handler.py", line 123, in handle_legacy_message_from_msgtype
    out_recorddict = getparametersres_to_recorddict(
                     ^^^^^^^^^^^^^^^^^^^^^^^^^^^^^^^
  File "/home/timotei/venv/lib/python3.12/site-packages/flwr/common/recorddict_compat.py", line 343, in getparametersres_to_recorddict
    getparametersres.parameters, keep_input=keep_input
    ^^^^^^^^^^^^^^^^^^^^^^^^^^^
AttributeError: 'Parameters' object has no attribute 'parameters'

The above exception was the direct cause of the following exception:

[36mray::ClientAppActor.run()[39m (pid=70868, ip=192.168.52.78, actor_id=b600b7835a21c5010eed2b8201000000, repr=<flwr.simulation.ray_transport.ray_actor.ClientAppActor object at 0x7f6fa6946030>)
           ^^^^^^^^^^^^^^^^^^^^^^^^^^^^^^^^^^^^
           ^^^^^^^^^^^^^^^^^^^^^^^^^^^^^^^
  File "/home/timotei/venv/lib/python3.12/site-packages/flwr/simulation/ray_transport/ray_actor.py", line 64, in run
    raise ClientAppException(str(ex)) from ex
flwr.client.client_app.ClientAppException: 
Exception ClientAppException occurred. Message: 'Parameters' object has no attribute 'parameters'

The above exception was the direct cause of the following exception:

Traceback (most recent call last):
  File "/home/timotei/federated-learning-human-mobility/fl_model/simulate_flower.py", line 54, in <module>
    fl.simulation.start_simulation(
  File "/home/timotei/venv/lib/python3.12/site-packages/flwr/simulation/legacy_app.py", line 397, in start_simulation
    raise RuntimeError("Simulation crashed.") from ex
RuntimeError: Simulation crashed.
[36m(pid=70869)[0m 2025-04-03 19:23:56.722047: I tensorflow/core/util/port.cc:153] oneDNN custom operations are on. You may see slightly different numerical results due to floating-point round-off errors from different computation orders. To turn them off, set the environment variable `TF_ENABLE_ONEDNN_OPTS=0`.[32m [repeated 7x across cluster] (Ray deduplicates logs by default. Set RAY_DEDUP_LOGS=0 to disable log deduplication, or see https://docs.ray.io/en/master/ray-observability/user-guides/configure-logging.html#log-deduplication for more options.)[0m
[36m(pid=70869)[0m 2025-04-03 19:23:56.724497: I external/local_xla/xla/tsl/cuda/cudart_stub.cc:32] Could not find cuda drivers on your machine, GPU will not be used.[32m [repeated 15x across cluster][0m
[36m(pid=70869)[0m 2025-04-03 19:23:56.731133: E external/local_xla/xla/stream_executor/cuda/cuda_fft.cc:467] Unable to register cuFFT factory: Attempting to register factory for plugin cuFFT when one has already been registered[32m [repeated 7x across cluster][0m
[36m(pid=70869)[0m WARNING: All log messages before absl::InitializeLog() is called are written to STDERR[32m [repeated 7x across cluster][0m
[36m(pid=70869)[0m E0000 00:00:1743704636.749165   70869 cuda_dnn.cc:8579] Unable to register cuDNN factory: Attempting to register factory for plugin cuDNN when one has already been registered[32m [repeated 7x across cluster][0m
[36m(pid=70869)[0m E0000 00:00:1743704636.754515   70869 cuda_blas.cc:1407] Unable to register cuBLAS factory: Attempting to register factory for plugin cuBLAS when one has already been registered[32m [repeated 7x across cluster][0m
[36m(pid=70869)[0m W0000 00:00:1743704636.768406   70869 computation_placer.cc:177] computation placer already registered. Please check linkage and avoid linking the same target more than once.[32m [repeated 28x across cluster][0m
[36m(pid=70869)[0m 2025-04-03 19:23:56.774550: I tensorflow/core/platform/cpu_feature_guard.cc:210] This TensorFlow binary is optimized to use available CPU instructions in performance-critical operations.[32m [repeated 7x across cluster][0m
[36m(pid=70869)[0m To enable the following instructions: AVX2 AVX_VNNI FMA, in other operations, rebuild TensorFlow with the appropriate compiler flags.[32m [repeated 7x across cluster][0m
